Workbook

Sheet Summary
A1: Code Review Assistant: human review of outputs
A2: Final run: version 1.2.0 on Kaggle (2x T4), answer-key labels hidden from the model.
A4: 1. Precision on code nobody here wrote (fresh stdlib sample, after the rule fixes)
A5: Category | B5: Findings | C5: Real | D5: False | E5: Unsure | F5: Precision
A6: bug | B6: =COUNTIF(Audit!$C$2:$C$51,"bug") -> 12 | C6: =COUNTIFS(Audit!$C$2:$C$51,"bug",Audit!$H$2:$H$51,"real") -> 3 | D6: =COUNTIFS(Audit!$C$2:$C$51,"bug",Audit!$H$2:$H$51,"false") -> 0 | E6: =COUNTIFS(Audit!$C$2:$C$51,"bug",Audit!$H$2:$H$51,"unsure") -> 0 | F6: =IFERROR(C6/(C6+D6),"-") -> 1
A7: security | B7: =COUNTIF(Audit!$C$2:$C$51,"security") -> 12 | C7: =COUNTIFS(Audit!$C$2:$C$51,"security",Audit!$H$2:$H$51,"real") -> 5 | D7: =COUNTIFS(Audit!$C$2:$C$51,"security",Audit!$H$2:$H$51,"false") -> 0 | E7: =COUNTIFS(Audit!$C$2:$C$51,"security",Audit!$H$2:$H$51,"unsure") -> 0 | F7: =IFERROR(C7/(C7+D7),"-") -> 1
A8: style | B8: =COUNTIF(Audit!$C$2:$C$51,"style") -> 13 | C8: =COUNTIFS(Audit!$C$2:$C$51,"style",Audit!$H$2:$H$51,"real") -> 3 | D8: =COUNTIFS(Audit!$C$2:$C$51,"style",Audit!$H$2:$H$51,"false") -> 0 | E8: =COUNTIFS(Audit!$C$2:$C$51,"style",Audit!$H$2:$H$51,"unsure") -> 0 | F8: =IFERROR(C8/(C8+D8),"-") -> 1
A9: optimization | B9: =COUNTIF(Audit!$C$2:$C$51,"optimization") -> 13 | C9: =COUNTIFS(Audit!$C$2:$C$51,"optimization",Audit!$H$2:$H$51,"real") -> 6 | D9: =COUNTIFS(Audit!$C$2:$C$51,"optimization",Audit!$H$2:$H$51,"false") -> 0 | E9: =COUNTIFS(Audit!$C$2:$C$51,"optimization",Audit!$H$2:$H$51,"unsure") -> 0 | F9: =IFERROR(C9/(C9+D9),"-") -> 1
A10: All | B10: =SUM(B6:B9) -> 50 | C10: =SUM(C6:C9) -> 17 | D10: =SUM(D6:D9) -> 0 | E10: =SUM(E6:E9) -> 0 | F10: =IFERROR(C10/(C10+D10),"-") -> 1
A11: Before the fixes (first sample, for comparison) | B11: =COUNTA('Audit before fixes'!$H$2:$H$51) -> 50 | C11: =COUNTIF('Audit before fixes'!$H$2:$H$51,"real") -> 13 | D11: =COUNTIF('Audit before fixes'!$H$2:$H$51,"false") -> 0 | E11: =COUNTIF('Audit before fixes'!$H$2:$H$51,"unsure") -> 0 | F11: =IFERROR(C11/(C11+D11),"-") -> 1
A13: By severity (fresh sample)
A14: Severity | B14: Findings | C14: Real | D14: False | E14: Unsure | F14: Precision
A15: critical | B15: =COUNTIF(Audit!$E$2:$E$51,"critical") -> 4 | C15: =COUNTIFS(Audit!$E$2:$E$51,"critical",Audit!$H$2:$H$51,"real") -> 1 | D15: =COUNTIFS(Audit!$E$2:$E$51,"critical",Audit!$H$2:$H$51,"false") -> 0 | E15: =COUNTIFS(Audit!$E$2:$E$51,"critical",Audit!$H$2:$H$51,"unsure") -> 0 | F15: =IFERROR(C15/(C15+D15),"-") -> 1
A16: high | B16: =COUNTIF(Audit!$E$2:$E$51,"high") -> 3 | C16: =COUNTIFS(Audit!$E$2:$E$51,"high",Audit!$H$2:$H$51,"real") -> 0 | D16: =COUNTIFS(Audit!$E$2:$E$51,"high",Audit!$H$2:$H$51,"false") -> 0 | E16: =COUNTIFS(Audit!$E$2:$E$51,"high",Audit!$H$2:$H$51,"unsure") -> 0 | F16: =IFERROR(C16/(C16+D16),"-") -> -
A17: medium | B17: =COUNTIF(Audit!$E$2:$E$51,"medium") -> 14 | C17: =COUNTIFS(Audit!$E$2:$E$51,"medium",Audit!$H$2:$H$51,"real") -> 4 | D17: =COUNTIFS(Audit!$E$2:$E$51,"medium",Audit!$H$2:$H$51,"false") -> 0 | E17: =COUNTIFS(Audit!$E$2:$E$51,"medium",Audit!$H$2:$H$51,"unsure") -> 0 | F17: =IFERROR(C17/(C17+D17),"-") -> 1
A18: low | B18: =COUNTIF(Audit!$E$2:$E$51,"low") -> 23 | C18: =COUNTIFS(Audit!$E$2:$E$51,"low",Audit!$H$2:$H$51,"real") -> 7 | D18: =COUNTIFS(Audit!$E$2:$E$51,"low",Audit!$H$2:$H$51,"false") -> 0 | E18: =COUNTIFS(Audit!$E$2:$E$51,"low",Audit!$H$2:$H$51,"unsure") -> 0 | F18: =IFERROR(C18/(C18+D18),"-") -> 1
A19: info | B19: =COUNTIF(Audit!$E$2:$E$51,"info") -> 6 | C19: =COUNTIFS(Audit!$E$2:$E$51,"info",Audit!$H$2:$H$51,"real") -> 5 | D19: =COUNTIFS(Audit!$E$2:$E$51,"info",Audit!$H$2:$H$51,"false") -> 0 | E19: =COUNTIFS(Audit!$E$2:$E$51,"info",Audit!$H$2:$H$51,"unsure") -> 0 | F19: =IFERROR(C19/(C19+D19),"-") -> 1
A21: Remaining sources of false positives (fresh sample)
A22: Rule | B22: Findings | C22: Real | D22: False
A23: B005 bare except (most re-raise) | B23: =COUNTIF(Audit!$D$2:$D$51,"B005") -> 7 | C23: =COUNTIFS(Audit!$D$2:$D$51,"B005",Audit!$H$2:$H$51,"real") -> 1 | D23: =COUNTIFS(Audit!$D$2:$D$51,"B005",Audit!$H$2:$H$51,"false") -> 0
A24: S002 exec() where running code is the purpose | B24: =COUNTIF(Audit!$D$2:$D$51,"S002") -> 4 | C24: =COUNTIFS(Audit!$D$2:$D$51,"S002",Audit!$H$2:$H$51,"real") -> 1 | D24: =COUNTIFS(Audit!$D$2:$D$51,"S002",Audit!$H$2:$H$51,"false") -> 0
A25: Y014 long lines (a generated file) | B25: =COUNTIF(Audit!$D$2:$D$51,"Y014") -> 5 | C25: =COUNTIFS(Audit!$D$2:$D$51,"Y014",Audit!$H$2:$H$51,"real") -> 0 | D25: =COUNTIFS(Audit!$D$2:$D$51,"Y014",Audit!$H$2:$H$51,"false") -> 0
A26: O004 list comprehension | B26: =COUNTIF(Audit!$D$2:$D$51,"O004") -> 7 | C26: =COUNTIFS(Audit!$D$2:$D$51,"O004",Audit!$H$2:$H$51,"real") -> 2 | D26: =COUNTIFS(Audit!$D$2:$D$51,"O004",Audit!$H$2:$H$51,"false") -> 0
A28: 2. Usefulness of the 7B model's explanations and fixes (1 to 5)
A29: Group | B29: Rows | C29: Average
A30: All rows | B30: =COUNT(Rating!$H$2:$H$21) -> 20 | C30: =IFERROR(AVERAGE(Rating!$H$2:$H$21),"-") -> 3.55
A31: Optimisation suggestions | B31: =COUNTIF(Rating!$C$2:$C$21,"optimization") -> 5 | C31: =IFERROR(AVERAGEIF(Rating!$C$2:$C$21,"optimization",Rating!$H$2:$H$21),"-") -> 3.6
A32: Model's own findings (LLM001) | B32: =COUNTIF(Rating!$D$2:$D$21,"LLM001") -> 3 | C32: =IFERROR(AVERAGEIF(Rating!$D$2:$D$21,"LLM001",Rating!$H$2:$H$21),"-") -> 3.3333333
A34: Score | B34: Rows
A35: 5 | B35: =COUNTIF(Rating!$H$2:$H$21,A35) -> 5
A36: 4 | B36: =COUNTIF(Rating!$H$2:$H$21,A36) -> 6
A37: 3 | B37: =COUNTIF(Rating!$H$2:$H$21,A37) -> 6
A38: 2 | B38: =COUNTIF(Rating!$H$2:$H$21,A38) -> 1
A39: 1 | B39: =COUNTIF(Rating!$H$2:$H$21,A39) -> 2
A41: 3. The 7B model on the 10 rule-blind bugs
A42: Outcome | B42: Automatic | C42: By hand
A43: Right | B43: =COUNTIF('Model findings'!$E$2:$E$11,"right") -> 3 | C43: =COUNTIF('Model findings'!$F$2:$F$11,"right") -> 3
A44: Wrong | B44: =COUNTIF('Model findings'!$E$2:$E$11,"wrong") -> 1 | C44: =COUNTIF('Model findings'!$F$2:$F$11,"wrong") -> 1
A45: Nothing reported | B45: =COUNTIF('Model findings'!$E$2:$E$11,"missed") -> 6 | C45: =COUNTIF('Model findings'!$F$2:$F$11,"missed") -> 6
A47: How to read this
...

Sheet Audit
A1: file | B1: line | C1: category | D1: rule | E1: severity | F1: issue | G1: code | H1: verdict | I1: comment
A2: _pydecimal.py | B2: 616 | C2: bug | D2: B008 | E2: medium | F2: Exact equality comparison against a float | G2: 614 if _math.isinf(f) or _math.isnan(f): 615 return cls(repr(f)) 616 if _math.copysign(1.0, f) == 1.0: 617 sign = 0 618 else: | H2: false | I2: copysign returns exactly 1.0 or -1.0, so == is exact here.
A3: _pydecimal.py | B3: 5947 | C3: bug | D3: B001 | E3: high | F3: Mutable default argument in '_log10_lb' | G3: 5945 return coeff, exp 5946 5947 def _log10_lb(c, correction = { 5948 '1': 100, '2': 70, '3': 53, '4': 40, '5': 31, 5949 '6': 23, '7': 16, '8': 10, '9': 5}): | H3: false | I3: Read-only lookup table bound as a default on purpose (fast local access); it is never mutated.
A4: unix_events.py | B4: 332 | C4: bug | D4: B005 | E4: medium | F4: Bare except catches everything, including KeyboardInterrupt | G4: 330 else: 331 raise 332 except: 333 sock.close() 334 raise | H4: false | I4: Cleanup, then a bare raise: catching everything is deliberate and the error still propagates.
A5: windows_utils.py | B5: 163 | C5: bug | D5: B005 | E5: medium | F5: Bare except catches everything, including KeyboardInterrupt | G5: 161 super().__init__(args, stdin=stdin_rfd, stdout=stdout_wfd, 162 stderr=stderr_wfd, **kwds) 163 except: 164 for h in (stdin_wh, stdout_rh, stderr_rh): 165 if h is not None: | H5: false | I5: Cleanup, then a bare raise: catching everything is deliberate and the error still propagates.
A6: bdb.py | B6: 461 | C6: bug | D6: B013 | E6: low | F6: 'bp' is assigned but never used in 'set_break' | G6: 459 return 'Line %s:%d does not exist' % (filename, lineno) 460 self._add_to_breaks(filename, lineno) 461 bp = Breakpoint(filename, lineno, temporary, cond, funcname) 462 # After we set a new breakpoint, we need to search through all frames 463 # and set f_trace to trace_dispatch if there could be a breakpoint in | H6: real | I6: True: the name bp is never used. The call is needed for its side effect, so only the binding should go.
A7: codecs.py | B7: 931 | C7: bug | D7: B005 | E7: medium | F7: Bare except catches everything, including KeyboardInterrupt | G7: 929 srw.encoding = encoding 930 return srw 931 except: 932 file.close() 933 raise | H7: false | I7: Cleanup, then a bare raise: catching everything is deliberate and the error still propagates.
A8: _parseaddr.py | B8: 52 | C8: bug | D8: B002 | E8: medium | F8: 'parsedate_tz' sometimes returns a value and sometimes returns None | G8: 50 res = _parsedate_tz(data) 51 if not res: 52 return 53 if res[9] is None: 54 res[9] = 0 | H8: real | I8: True: bare 'return' mixed with 'return value'. PEP 8 asks for an explicit 'return None'. Style, not a bug.
A9: selectors.py | B9: 373 | C9: bug | D9: B005 | E9: medium | F9: Bare except catches everything, including KeyboardInterrupt | G9: 371 try: 372 self._selector.modify(key.fd, selector_events) 373 except: 374 super().unregister(fileobj) 375 raise | H9: false | I9: Cleanup, then a bare raise: catching everything is deliberate and the error still propagates.
A10: selectors.py | B10: 512 | C10: bug | D10: B005 | E10: medium | F10: Bare except catches everything, including KeyboardInterrupt | G10: 510 self._selector.control([kev], 0, 0) 511 self._max_events += 1 512 except: 513 super().unregister(fileobj) 514 raise | H10: false | I10: Cleanup, then a bare raise: catching everything is deliberate and the error still propagates.
A11: threading.py | B11: 1016 | C11: bug | D11: B005 | E11: medium | F11: Bare except catches everything, including KeyboardInterrupt | G11: 1014 try: 1015 self._bootstrap_inner() 1016 except: 1017 if self._daemonic and _sys is None: 1018 return | H11: false | I11: Thread bootstrap during interpreter shutdown: catching everything is deliberate.
A12: turtle.py | B12: 2747 | C12: bug | D12: B008 | E12: medium | F12: Exact equality comparison against a float | G12: 2745 except (TypeError, ValueError): 2746 raise TurtleGraphicsError("bad color arguments: %s" % str(args)) 2747 if self.screen._colormode == 1.0: 2748 r, g, b = [round(255.0*x) for x in (r, g, b)] 2749 if not ((0 <= r <= 255) and (0 <= g <= 255) and (0 <= b <= 255)): | H12: false | I12: colormode is set to exactly 1.0 or 255, never computed, so == is exact.
A13: uuid.py | B13: 656 | C13: bug | D13: B005 | E13: medium | F13: Bare except catches everything, including KeyboardInterrupt | G13: 654 try: 655 _node = getter() 656 except: 657 continue 658 if (_node is not None) and (0 <= _node < (1 << 48)): | H13: real | I13: Real: 'except: continue' also swallows KeyboardInterrupt and SystemExit; 'except Exception' is meant.
... A51: xmlbuilder.py | B51: 41 | C51: style | D51: Y011 | E51: medium | F51: 'filter' shadows a builtin | G51: 39 40 errorHandler = None 41 filter = None 42 43 | H51: false | I51: 'filter' is an attribute name fixed by the DOM Level 3 spec, not a shadowed builtin.

Sheet Audit before fixes
A1: file | B1: line | C1: category | D1: rule | E1: severity | F1: issue | G1: code | H1: verdict | I1: comment
A2: unix_console.py | B2: 274 | C2: bug | D2: B013 | E2: low | F2: 'py' is assigned but never used in 'refresh' | G2: 272 self.__move = self.__move_tall 273 274 px, py = self.posxy 275 old_offset = offset = self.__offset 276 height = self.height | H2: false | I2: Tuple unpacking: the call returns several values and the unused one has to be named. Not a bug.
A3: codecs.py | B3: 380 | C3: bug | D3: B013 | E3: low | F3: 'consumed' is assigned but never used in 'write' | G3: 378 """ Writes the object's contents encoded to self.stream. 379 """ 380 data, consumed = self.encode(object, self.errors) 381 self.stream.write(data) 382 | H3: false | I3: Tuple unpacking: the call returns several values and the unused one has to be named. Not a bug.
A4: codecs.py | B4: 833 | C4: bug | D4: B013 | E4: low | F4: 'bytesencoded' is assigned but never used in 'readlines' | G4: 831 832 data = self.reader.read() 833 data, bytesencoded = self.encode(data, self.errors) 834 return data.splitlines(keepends=True) 835 | H4: false | I4: Tuple unpacking: the call returns several values and the unused one has to be named. Not a bug.
A5: codecs.py | B5: 840 | C5: bug | D5: B013 | E5: low | F5: 'bytesencoded' is assigned but never used in '__next__' | G5: 838 """ Return the next decoded line from the input stream.""" 839 data = next(self.reader) 840 data, bytesencoded = self.encode(data, self.errors) 841 return data 842 | H5: false | I5: Tuple unpacking: the call returns several values and the unused one has to be named. Not a bug.
A6: colorsys.py | B6: 146 | C6: bug | D6: B008 | E6: medium | F6: Exact equality comparison against a float | G6: 144 145 def hsv_to_rgb(h, s, v): 146 if s == 0.0: 147 return v, v, v 148 i = int(h*6.0) # XXX assume int() truncates! | H6: false | I6: Exact zero is the intended special case (no saturation), not a computed float. Comparing with == 0.0 is correct here.
A7: cookiejar.py | B7: 1750 | C7: bug | D7: B011 | E7: high | F7: 'self' is modified while being iterated over | G7: 1748 for cookie in self: 1749 if cookie.is_expired(now): 1750 self.clear(cookie.domain, cookie.path, cookie.name) 1751 finally: 1752 self._cookies_lock.release() | H7: false | I7: The jar's iterator walks list(mapping.values()), a copy, so clearing cookies during the loop is safe.
A8: __init__.py | B8: 565 | C8: bug | D8: B002 | E8: medium | F8: '_read_files_egginfo_installed' sometimes returns a value and sometimes returns None | G8: 563 subdir = getattr(self, '_path', None) 564 if not text or not subdir: 565 return 566 567 paths = ( | H8: real | I8: True: mixes bare 'return' with 'return map(...)'. PEP 8 asks for an explicit 'return None'. A style point, not a bug as labelled.
A9: __init__.py | B9: 950 | C9: bug | D9: B013 | E9: low | F9: 'sep' is assigned but never used in '_name_from_stem' | G9: 948 if ext not in ('.dist-info', '.egg-info'): 949 return 950 name, sep, rest = filename.partition('-') 951 return name 952 | H9: false | I9: Tuple unpacking: the call returns several values and the unused one has to be named. Not a bug.
A10: socketserver.py | B10: 322 | C10: bug | D10: B005 | E10: medium | F10: Bare except catches everything, including KeyboardInterrupt | G10: 320 self.handle_error(request, client_address) 321 self.shutdown_request(request) 322 except: 323 self.shutdown_request(request) 324 raise | H10: false | I10: Bare except that cleans up and re-raises. Catching everything is deliberate and correct.
A11: tokenize.py | B11: 213 | C11: bug | D11: B013 | E11: low | F11: 'char' is assigned but never used in 'escape_brackets' | G11: 211 if character == "{": 212 n_backslashes = sum( 213 1 for char in _itertools.takewhile( 214 "\\".__eq__, 215 characters[-2::-1] | H11: false | I11: Counting idiom: sum(1 for char in ...). The loop variable is never meant to be used.
A12: turtle.py | B12: 3018 | C12: bug | D12: B013 | E12: low | F12: 'a21' is assigned but never used in 'shapetransform' | G12: 3016 alfa = math.atan2(-m21, m11) % math.tau 3017 sa, ca = math.sin(alfa), math.cos(alfa) 3018 a11, a12, a21, a22 = (ca*m11 - sa*m21, ca*m12 - sa*m22, 3019 sa*m11 + ca*m21, sa*m12 + ca*m22) 3020 self._stretchfactor = a11, a22 | H12: real | I12: a21 is computed (sa*m11 + ca*m21) and never used: dead arithmetic. Low impact.
A13: turtle.py | B13: 3503 | C13: bug | D13: B013 | E13: low | F13: 'x' is assigned but never used in 'write' | G13: 3501 end = self._write(str(arg), align.lower(), font) 3502 if move: 3503 x, y = self.pos() 3504 self.setpos(end, y) 3505 if self.undobuffer: | H13: false | I13: Tuple unpacking: the call returns several values and the unused one has to be named. Not a bug.
... A51: pulldom.py | B51: 188 | C51: style | D51: Y003 | E51: low | F51: Function name 'endDocument' is not snake_case | G51: 186 return node.firstChild 187 188 def endDocument(self): 189 self.lastEvent[1] = [(END_DOCUMENT, self.document), None] 190 self.pop() | H51: false | I51: SAX handler method: the name is fixed by the xml.sax interface.

Sheet Rating
A1: file | B1: line | C1: category | D1: rule | E1: issue | F1: explanation | G1: fix | H1: usefulness_1_to_5 | I1: comment
A2: comprehension_in_sum.py | B2: 6 | C2: optimization | D2: O006 | E2: sum() given a list comprehension | F2: The use of a list comprehension inside the sum function can be optimized by using the built-in `sum` function directly with a generator expression, which avoids creating an intermediate list. | G2: return sum(v for v in values if v > 0) | H2: 4 | I2: Correct and the fix is exact code. The gain is memory, not speed: in CPython a list comprehension inside sum() is often slightly faster.
A3: range_len.py | B3: 7 | C3: optimization | D3: O001 | E3: for i in range(len(x)) can be enumerate(x) | F3: Using `enumerate(items)` directly makes the code more readable and efficient by eliminating the need to call `len(items)` multiple times. | G3: for i, item in enumerate(items): | H3: 3 | I3: Fix is right but incomplete (the body still uses items[i]), and the reason is wrong: len(items) is called once, not 'multiple times'.
A4: redundant_keys.py | B4: 7 | C4: optimization | D4: O002 | E4: Iterating over .keys() is redundant | F4: The method `mapping.keys()` returns a view object that displays a list of all the keys in the dictionary. Iterating over this view directly is more efficient than calling `.keys()` and then iterating over the result. | G4: for key in mapping: | H4: 3 | I4: Fix is right; the explanation is muddled (.keys() does not return a list) and the speed claim is negligible. The real point is readability.
A5: redundant_keys.py | B5: 14 | C5: optimization | D5: O007 | E5: Membership test against a list/tuple literal | F5: Checking membership against a list can be optimized by using a set, which provides faster lookup times. | G5: return day.lower() in {'sat', 'sun', 'saturday', 'sunday'} | H5: 5 | I5: Correct, specific, and the fix is ready to paste.
A6: string_concat_loop.py | B6: 8 | C6: optimization | D6: O003 | E6: String 'out' is built by repeated concatenation | F6: Building strings by repeated concatenation can lead to performance issues because strings in Python are immutable. This operation creates a new string object every time, which can be inefficient. | G6: Use `str.join()` instead of repeated concatenation. | H6: 3 | I6: Correct but generic, with no code. Should be: return ''.join(f'{row}\n' for row in rows).
A7: assert_tuple.py | B7: 6 | C7: bug | D7: B010 | E7: assert on a tuple literal is always true | F7: The assertion checks if the length of 'items' is greater than 0, which will always evaluate to a boolean value. This assertion is redundant because it's impossible for the condition to ever be false. | G7: Remove the assertion since it doesn't serve any purpose. | H7: 1 | I7: Wrong reason and a harmful fix. The bug is that assert (cond, msg) tests a non-empty tuple, so it never fails; removing it loses the check. Correct: assert len(items) > 0, 'items must not be empty'.
A8: complex_function.py | B8: 4 | C8: style | D8: Y005 | E8: 'grade' takes 6 parameters (limit 5) | F8: The 'grade' function takes six parameters, which exceeds the recommended limit of five. | G8: Consider removing one parameter or refactoring the function to use a dictionary or class to pass multiple values. | H8: 3 | I8: Restates the rule; the advice is generic but points in the right direction (group the flags).
A9: duplicate_dict_key.py | B9: 6 | C9: bug | D9: B009 | E9: Duplicate key 'retries' in dict literal | F9: The dictionary contains duplicate keys ('retries'), which will cause the last value to overwrite previous values. | G9: Remove the duplicate 'retries' key on line 6. | H9: 4 | I9: Correct and concrete, but removing line 6 keeps retries=3 while the code currently uses 5; it should say which value was meant.
A10: early_return_search.py | B10: 9 | C10: bug | D10: LLM001 | E10: The 'return None' statement is inside the loop, causing the function to return after checking only the first user. | F10: The current implementation returns None immediately after checking the first user, which means it will never check other users even if they match the user_id. | G10: Move the 'return None' statement outside the loop so that it executes only if no matching user is found after iterating through all users. | H10: 5 | I10: Correct diagnosis and the right fix, reasoned from the code.
A11: empty_average.py | B11: 6 | C11: bug | D11: LLM001 | E11: Division by zero if 'values' is empty. | F11: The function attempts to divide by the length of 'values', which will be zero if 'values' is empty, leading to a division by zero error. | G11: return sum(values) / max(len(values), 1) | H11: 4 | I11: Correct and matches the docstring. Returns int 0 rather than 0.0; 'if not values: return 0.0' is clearer.
A12: float_equality.py | B12: 6 | C12: bug | D12: B008 | E12: Exact equality comparison against a float | F12: Comparing a floating-point number directly to another floating-point number using '==' can lead to unexpected results due to precision issues. | G12: Use a tolerance value when comparing floats. | H12: 3 | I12: Correct but generic: no tolerance or code given. math.isclose(amount, 0.0, abs_tol=1e-9), or Decimal for money, would be the useful fix.
A13: hardcoded_secret.py | B13: 4 | C13: security | D13: S012 | E13: Hardcoded credential in 'API_KEY' | F13: The API key is hardcoded into the source code, which can lead to security vulnerabilities if the code is shared or exposed. | G13: Remove the hard-coded API key and use environment variables or configuration files instead. | H13: 4 | I13: Correct, standard advice. Generic, but it is the right fix.
... A21: none_comparison.py | B21: 13 | C21: bug | D21: B007 | E21: Comparing to True explicitly | F21: Explicitly comparing with True can lead to bugs if the flag variable is not always a boolean. | G21: return bool(flag) | H21: 4 | I21: Reasonable, but bool(flag) changes behaviour for truthy non-bool values such as 'yes'. 'flag is True' keeps the strict meaning.

Sheet Model findings
A1: case | B1: the bug | C1: model said | D1: confidence | E1: scored automatically | F1: checked by hand | G1: comment
A2: off_by_one_sum | B2: range(1, ...) skips the first price | C2: Off-by-one error in loop range. | D2: 0.9 | E2: right | F2: right | G2: Terse, but names the bug.
A3: wrong_boundary | B3: > where >= was meant | E3: missed | F3: missed | G3: Nothing reported.
A4: empty_average | B4: divides by zero on an empty list | C4: Division by zero if 'values' is empty. | D4: 0.9 | E4: right | F4: right | G4: Names the empty-list division by zero.
A5: unclosed_file | B5: file handle is never closed | E5: missed | F5: missed | G5: Nothing reported.
A6: sign_of_zero | B6: zero is treated as negative | E6: missed | F6: missed | G6: Nothing reported (found in earlier runs, when the label was visible).
A7: early_return_search | B7: gives up after the first user | C7: The 'return None' statement is inside the loop, causing the function to return after checking only the first user. | D7: 0.9 | E7: right | F7: right | G7: Correct, and the fix is right.
A8: swapped_transfer | B8: money moves the wrong way | E8: missed | F8: missed | G8: Nothing reported (found in earlier runs, when the label was visible).
A9: missing_increment | B9: i is never incremented | C9: The loop condition should include 'limit' to ensure all numbers up to 'limit' are included. | D9: 0.9 | E9: wrong | F9: wrong | G9: Wrong line (10) and wrong reason: suggests <=, but the real bug is the missing i += 1.
A10: floor_division_share | B10: // drops the paise | E10: missed | F10: missed | G10: Nothing reported.
A11: latest_zero | B11: n == 0 returns every post | E11: missed | F11: missed | G11: Nothing reported.
